Workbook
Name SlicerCache_Table_2_Col_4: #N/A
Name SlicerCache_Table_2_Col_5: #N/A
Name SlicerCache_Table_2_Col_6: #N/A
Name SlicerCache_Table_2_Col_8: #N/A

Sheet Dataset
A1: Row ID | B1: Order Priority | C1: Discount | D1: Unit Price | E1: Customer ID | F1: Customer Name | G1: Customer Segment | H1: Product Category | I1: Product Sub-Category | J1: Product Name | K1: City | L1: Order Weekday | M1: Weekday helper | N1: Profit | O1: Quantity ordered new | P1: Sales | Q1: Order ID | R1: Order returned | S1: Order Date
A2: 20847 | B2: High | C2: 0.01 | D2: 2.84 | E2: 3 | F2: Bonnie Potter | G2: Corporate | H2: Office Supplies | I2: Pens & Art Supplies | J2: SANFORD Liquid Accent™ Tank-Style Highlighters | K2: Warsaw | L2: Wednesday | M2: =VLOOKUP(L2,$U$2:$V$8,2,0) -> 3 | N2: 4.56 | O2: 4 | P2: 13.01 | Q2: 88522 | R2: =ISNUMBER(MATCH(Q2,'Returned order'!A:A,0)) -> FALSE | S2: 42011 | U2: Monday | V2: 1
A3: 20228 | B3: Not Specified | C3: 0.02 | D3: 500.98 | E3: 5 | F3: Ronnie Proctor | G3: Home Office | H3: Furniture | I3: Chairs & Chairmats | J3: Global Troy™ Executive Leather Low-Back Tilter | K3: Warsaw | L3: Saturday | M3: =VLOOKUP(L3,$U$2:$V$8,2,0) -> 6 | N3: 4390.3665 | O3: 12 | P3: 6362.85 | Q3: 90193 | R3: =ISNUMBER(MATCH(Q3,'Returned order'!A:A,0)) -> FALSE | S3: 42168 | U3: Tuesday | V3: 2
A4: 21776 | B4: Critical | C4: 0.06 | D4: 9.48 | E4: 11 | F4: Marcus Dunlap | G4: Home Office | H4: Furniture | I4: Office Furnishings | J4: DAX Two-Tone Rosewood/Black Document Frame, Desktop, 5 x 7 | K4: Lodz | L4: Sunday | M4: =VLOOKUP(L4,$U$2:$V$8,2,0) -> 7 | N4: -53.8096 | O4: 22 | P4: 211.15 | Q4: 90192 | R4: =ISNUMBER(MATCH(Q4,'Returned order'!A:A,0)) -> FALSE | S4: 42050 | U4: Wednesday | V4: 3
A5: 24844 | B5: Medium | C5: 0.09 | D5: 78.69 | E5: 14 | F5: Gwendolyn F Tyson | G5: Small Business | H5: Furniture | I5: Office Furnishings | J5: Howard Miller 12-3/4 Diameter Accuwave DS ™ Wall Clock | K5: Krakow | L5: Tuesday | M5: =VLOOKUP(L5,$U$2:$V$8,2,0) -> 2 | N5: 803.4705 | O5: 16 | P5: 1164.45 | Q5: 86838 | R5: =ISNUMBER(MATCH(Q5,'Returned order'!A:A,0)) -> FALSE | S5: 42136 | U5: Thursday | V5: 4
A6: 24846 | B6: Medium | C6: 0.08 | D6: 3.28 | E6: 14 | F6: Gwendolyn F Tyson | G6: Small Business | H6: Office Supplies | I6: Pens & Art Supplies | J6: Newell 321 | K6: Krakow | L6: Tuesday | M6: =VLOOKUP(L6,$U$2:$V$8,2,0) -> 2 | N6: -24.03 | O6: 7 | P6: 22.23 | Q6: 86838 | R6: =ISNUMBER(MATCH(Q6,'Returned order'!A:A,0)) -> FALSE | S6: 42136 | U6: Friday | V6: 5
A7: 24847 | B7: Medium | C7: 0.05 | D7: 3.28 | E7: 14 | F7: Gwendolyn F Tyson | G7: Small Business | H7: Office Supplies | I7: Pens & Art Supplies | J7: Newell 351 | K7: Krakow | L7: Tuesday | M7: =VLOOKUP(L7,$U$2:$V$8,2,0) -> 2 | N7: -37.03 | O7: 4 | P7: 13.99 | Q7: 86838 | R7: =ISNUMBER(MATCH(Q7,'Returned order'!A:A,0)) -> FALSE | S7: 42136 | U7: Saturday | V7: 6
A8: 24848 | B8: Medium | C8: 0.05 | D8: 3.58 | E8: 14 | F8: Gwendolyn F Tyson | G8: Small Business | H8: Office Supplies | I8: Rubber Bands | J8: OIC Colored Binder Clips, Assorted Sizes | K8: Krakow | L8: Tuesday | M8: =VLOOKUP(L8,$U$2:$V$8,2,0) -> 2 | N8: -0.71 | O8: 4 | P8: 14.26 | Q8: 86838 | R8: =ISNUMBER(MATCH(Q8,'Returned order'!A:A,0)) -> FALSE | S8: 42136 | U8: Sunday | V8: 7
A9: 18181 | B9: Critical | C9: 0 | D9: 4.42 | E9: 15 | F9: Timothy Reese | G9: Small Business | H9: Office Supplies | I9: Envelopes | J9: Grip Seal Envelopes | K9: Lodz | L9: Wednesday | M9: =VLOOKUP(L9,$U$2:$V$8,2,0) -> 3 | N9: -59.82 | O9: 7 | P9: 33.47 | Q9: 86837 | R9: =ISNUMBER(MATCH(Q9,'Returned order'!A:A,0)) -> FALSE | S9: 42102
A10: 20925 | B10: Medium | C10: 0.01 | D10: 35.94 | E10: 15 | F10: Timothy Reese | G10: Small Business | H10: Office Supplies | I10: Envelopes | J10: Tyvek ® Top-Opening Peel & Seel ® Envelopes, Gray | K10: Lodz | L10: Thursday | M10: =VLOOKUP(L10,$U$2:$V$8,2,0) -> 4 | N10: 261.8757 | O10: 10 | P10: 379.53 | Q10: 86839 | R10: =ISNUMBER(MATCH(Q10,'Returned order'!A:A,0)) -> FALSE | S10: 42152
A11: 26267 | B11: High | C11: 0.04 | D11: 2.98 | E11: 16 | F11: Sarah Ramsey | G11: Small Business | H11: Office Supplies | I11: Rubber Bands | J11: Staples Gold Paper Clips | K11: Lodz | L11: Thursday | M11: =VLOOKUP(L11,$U$2:$V$8,2,0) -> 4 | N11: 2.63 | O11: 6 | P11: 18.8 | Q11: 86836 | R11: =ISNUMBER(MATCH(Q11,'Returned order'!A:A,0)) -> FALSE | S11: 42047
A12: 26268 | B12: High | C12: 0.05 | D12: 115.99 | E12: 16 | F12: Sarah Ramsey | G12: Small Business | H12: Technology | I12: Telephones and Communication | J12: StarTAC 7797 | K12: Lodz | L12: Thursday | M12: =VLOOKUP(L12,$U$2:$V$8,2,0) -> 4 | N12: 652.7331 | O12: 10 | P12: 945.99 | Q12: 86836 | R12: =ISNUMBER(MATCH(Q12,'Returned order'!A:A,0)) -> FALSE | S12: 42047
A13: 23890 | B13: High | C13: 0.05 | D13: 26.48 | E13: 18 | F13: Laurie Hanna | G13: Small Business | H13: Furniture | I13: Office Furnishings | J13: DAX Natural Wood-Tone Poster Frame | K13: Warsaw | L13: Friday | M13: =VLOOKUP(L13,$U$2:$V$8,2,0) -> 5 | N13: 314.4813 | O13: 17 | P13: 455.77 | Q13: 90031 | R13: =ISNUMBER(MATCH(Q13,'Returned order'!A:A,0)) -> FALSE | S13: 42139
A14: 24063 | B14: Not Specified | C14: 0.07 | D14: 12.99 | E14: 19 | F14: Jim Rodgers | G14: Small Business | H14: Technology | I14: Office Machines | J14: Hewlett Packard 6S Scientific Calculator | K14: Warsaw | L14: Thursday | M14: =VLOOKUP(L14,$U$2:$V$8,2,0) -> 4 | N14: -114.6399 | O14: 18 | P14: 231.79 | Q14: 90032 | R14: =ISNUMBER(MATCH(Q14,'Returned order'!A:A,0)) -> FALSE | S14: 42145
A15: 5890 | B15: High | C15: 0.05 | D15: 26.48 | E15: 21 | F15: Tony Wilkins Winters | G15: Small Business | H15: Furniture | I15: Office Furnishings | J15: DAX Natural Wood-Tone Poster Frame | K15: Lodz | L15: Friday | M15: =VLOOKUP(L15,$U$2:$V$8,2,0) -> 5 | N15: 384.38 | O15: 70 | P15: 1876.69 | Q15: 41793 | R15: =ISNUMBER(MATCH(Q15,'Returned order'!A:A,0)) -> FALSE | S15: 42139
A16: 6062 | B16: Not Specified | C16: 0.08 | D16: 5 | E16: 21 | F16: Tony Wilkins Winters | G16: Small Business | H16: Office Supplies | I16: Rubber Bands | J16: Advantus Plastic Paper Clips | K16: Lodz | L16: Thursday | M16: =VLOOKUP(L16,$U$2:$V$8,2,0) -> 4 | N16: -17.49 | O16: 58 | P16: 293.06 | Q16: 42949 | R16: =ISNUMBER(MATCH(Q16,'Returned order'!A:A,0)) -> FALSE | S16: 42145
A17: 6063 | B17: Not Specified | C17: 0.07 | D17: 12.99 | E17: 21 | F17: Tony Wilkins Winters | G17: Small Business | H17: Technology | I17: Office Machines | J17: Hewlett Packard 6S Scientific Calculator | K17: Lodz | L17: Thursday | M17: =VLOOKUP(L17,$U$2:$V$8,2,0) -> 4 | N17: -114.6399 | O17: 71 | P17: 914.29 | Q17: 42949 | R17: =ISNUMBER(MATCH(Q17,'Returned order'!A:A,0)) -> FALSE | S17: 42145
A18: 20631 | B18: High | C18: 0.06 | D18: 55.48 | E18: 24 | F18: Edna Thomas | G18: Corporate | H18: Office Supplies | I18: Paper | J18: Xerox 194 | K18: Warsaw | L18: Wednesday | M18: =VLOOKUP(L18,$U$2:$V$8,2,0) -> 3 | N18: -28.2968 | O18: 1 | P18: 67.49 | Q18: 87651 | R18: =ISNUMBER(MATCH(Q18,'Returned order'!A:A,0)) -> FALSE | S18: 42032
A19: 20632 | B19: High | C19: 0.02 | D19: 1.68 | E19: 24 | F19: Edna Thomas | G19: Corporate | H19: Office Supplies | I19: Pens & Art Supplies | J19: Newell 323 | K19: Warsaw | L19: Wednesday | M19: =VLOOKUP(L19,$U$2:$V$8,2,0) -> 3 | N19: -5.3072 | O19: 1 | P19: 2.25 | Q19: 87651 | R19: =ISNUMBER(MATCH(Q19,'Returned order'!A:A,0)) -> FALSE | S19: 42032
A20: 23967 | B20: Not Specified | C20: 0.04 | D20: 4.14 | E20: 27 | F20: Guy Gallagher | G20: Corporate | H20: Furniture | I20: Office Furnishings | J20: Eldon Image Series Black Desk Accessories | K20: Warsaw | L20: Saturday | M20: =VLOOKUP(L20,$U$2:$V$8,2,0) -> 6 | N20: 8.894 | O20: 12 | P20: 54.78 | Q20: 87652 | R20: =ISNUMBER(MATCH(Q20,'Returned order'!A:A,0)) -> FALSE | S20: 42126
... A27: 25933 | B27: High | C27: 0 | D27: 99.99 | E27: 43 | F27: Theodore Moran | G27: Consumer | H27: Technology | I27: Office Machines | J27: AT&T 2230 Dual Handset Phone With Caller ID/Call Waiting | K27: Warsaw | L27: Sunday | M27: =VLOOKUP(L27,$U$2:$V$8,2,0) -> 7 | N27: 25.91382 | O27: 6 | P27: 647.07 | Q27: 91454 | R27: =ISNUMBER(MATCH(Q27,'Returned order'!A:A,0)) -> FALSE | S27: 42134
A28: 18551 | B28: Not Specified | C28: 0 | D28: 115.99 | E28: 52 | F28: Lorraine Kelly | G28: Corporate | H28: Technology | I28: Telephones and Communication | J28: 6160 | K28: Warsaw | L28: Tuesday | M28: =VLOOKUP(L28,$U$2:$V$8,2,0) -> 2 | N28: 162.666 | O28: 6 | P28: 627.04 | Q28: 88426 | R28: =ISNUMBER(MATCH(Q28,'Returned order'!A:A,0)) -> FALSE | S28: 42073
A29: 22117 | B29: Critical | C29: 0.07 | D29: 3502.14 | E29: 53 | F29: Sidney Russell Austin | G29: Corporate | H29: Technology | I29: Office Machines | J29: Okidata Pacemark 4410N Wide Format Dot Matrix Printer | K29: Warsaw | L29: Wednesday | M29: =VLOOKUP(L29,$U$2:$V$8,2,0) -> 3 | N29: -6923.5992 | O29: 1 | P29: 3267.55 | Q29: 88425 | R29: =ISNUMBER(MATCH(Q29,'Returned order'!A:A,0)) -> FALSE | S29: 42032
A30: 18552 | B30: Not Specified | C30: 0.02 | D30: 5.98 | E30: 53 | F30: Sidney Russell Austin | G30: Corporate | H30: Office Supplies | I30: Paper | J30: Xerox 1903 | K30: Warsaw | L30: Tuesday | M30: =VLOOKUP(L30,$U$2:$V$8,2,0) -> 2 | N30: -67.49 | O30: 17 | P30: 110.19 | Q30: 88426 | R30: =ISNUMBER(MATCH(Q30,'Returned order'!A:A,0)) -> FALSE | S30: 42073
A31: 20697 | B31: Medium | C31: 0.06 | D31: 3.8 | E31: 56 | F31: Randall Montgomery | G31: Consumer | H31: Office Supplies | I31: Binders and Binder Accessories | J31: Durable Pressboard Binders | K31: Lodz | L31: Monday | M31: =VLOOKUP(L31,$U$2:$V$8,2,0) -> 1 | N31: 19.6282 | O31: 20 | P31: 73.55 | Q31: 88075 | R31: =ISNUMBER(MATCH(Q31,'Returned order'!A:A,0)) -> FALSE | S31: 42114
A32: 20698 | B32: Medium | C32: 0.06 | D32: 1.76 | E32: 56 | F32: Randall Montgomery | G32: Consumer | H32: Office Supplies | I32: Pens & Art Supplies | J32: Newell 310 | K32: Lodz | L32: Monday | M32: =VLOOKUP(L32,$U$2:$V$8,2,0) -> 1 | N32: -1.6524 | O32: 17 | P32: 29.57 | Q32: 88075 | R32: =ISNUMBER(MATCH(Q32,'Returned order'!A:A,0)) -> FALSE | S32: 42114
A33: 22890 | B33: High | C33: 0.02 | D33: 5.98 | E33: 62 | F33: Pam Gilbert | G33: Corporate | H33: Office Supplies | I33: Paper | J33: Xerox 193 | K33: Krakow | L33: Saturday | M33: =VLOOKUP(L33,$U$2:$V$8,2,0) -> 6 | N33: 2.14 | O33: 3 | P33: 22.85 | Q33: 87407 | R33: =ISNUMBER(MATCH(Q33,'Returned order'!A:A,0)) -> FALSE | S33: 42133
A34: 25354 | B34: High | C34: 0.04 | D34: 29.14 | E34: 62 | F34: Pam Gilbert | G34: Corporate | H34: Office Supplies | I34: Paper | J34: Snap-A-Way® Black Print Carbonless Speed Message, No Reply Area, Duplicate | K34: Krakow | L34: Friday | M34: =VLOOKUP(L34,$U$2:$V$8,2,0) -> 5 | N34: 349.4091 | O34: 17 | P34: 506.39 | Q34: 87408 | R34: =ISNUMBER(MATCH(Q34,'Returned order'!A:A,0)) -> FALSE | S34: 42167
A35: 21017 | B35: Not Specified | C35: 0 | D35: 3.69 | E35: 64 | F35: Lynn Morrow | G35: Small Business | H35: Office Supplies | I35: Labels | J35: Avery 501 | K35: Wroclaw | L35: Monday | M35: =VLOOKUP(L35,$U$2:$V$8,2,0) -> 1 | N35: -37.5291 | O35: 1 | P35: 4 | Q35: 87406 | R35: =ISNUMBER(MATCH(Q35,'Returned order'!A:A,0)) -> FALSE | S35: 42065
A36: 21019 | B36: Not Specified | C36: 0.02 | D36: 175.99 | E36: 64 | F36: Lynn Morrow | G36: Small Business | H36: Technology | I36: Telephones and Communication | J36: 5165 | K36: Wroclaw | L36: Monday | M36: =VLOOKUP(L36,$U$2:$V$8,2,0) -> 1 | N36: 101.49 | O36: 4 | P36: 589.8 | Q36: 87406 | R36: =ISNUMBER(MATCH(Q36,'Returned order'!A:A,0)) -> FALSE | S36: 42065
A37: 23274 | B37: Low | C37: 0.05 | D37: 155.06 | E37: 67 | F37: Ellen McCormick | G37: Corporate | H37: Office Supplies | I37: Storage & Organization | J37: Dual Level, Single-Width Filing Carts | K37: Warsaw | L37: Friday | M37: =VLOOKUP(L37,$U$2:$V$8,2,0) -> 5 | N37: 845.664 | O37: 8 | P37: 1225.6 | Q37: 87946 | R37: =ISNUMBER(MATCH(Q37,'Returned order'!A:A,0)) -> FALSE | S37: 42006
A38: 5272 | B38: Low | C38: 0 | D38: 291.73 | E38: 68 | F38: Scott Bunn | G38: Corporate | H38: Furniture | I38: Chairs & Chairmats | J38: Hon 4070 Series Pagoda™ Armless Upholstered Stacking Chairs | K38: Lodz | L38: Friday | M38: =VLOOKUP(L38,$U$2:$V$8,2,0) -> 5 | N38: -308.928 | O38: 4 | P38: 1239.06 | Q38: 37537 | R38: =ISNUMBER(MATCH(Q38,'Returned order'!A:A,0)) -> FALSE | S38: 42006
A39: 5273 | B39: Low | C39: 0.07 | D39: 100.98 | E39: 68 | F39: Scott Bunn | G39: Corporate | H39: Furniture | I39: Chairs & Chairmats | J39: Hon Valutask™ Swivel Chairs | K39: Lodz | L39: Friday | M39: =VLOOKUP(L39,$U$2:$V$8,2,0) -> 5 | N39: -1679.76 | O39: 43 | P39: 4083.19 | Q39: 37537 | R39: =ISNUMBER(MATCH(Q39,'Returned order'!A:A,0)) -> FALSE | S39: 42006
A40: 5274 | B40: Low | C40: 0.05 | D40: 155.06 | E40: 68 | F40: Scott Bunn | G40: Corporate | H40: Office Supplies | I40: Storage & Organization | J40: Dual Level, Single-Width Filing Carts | K40: Lodz | L40: Friday | M40: =VLOOKUP(L40,$U$2:$V$8,2,0) -> 5 | N40: 575.396 | O40: 32 | P40: 4902.38 | Q40: 37537 | R40: =ISNUMBER(MATCH(Q40,'Returned order'!A:A,0)) -> FALSE | S40: 42006
A41: 7786 | B41: High | C41: 0.09 | D41: 122.99 | E41: 68 | F41: Scott Bunn | G41: Corporate | H41: Furniture | I41: Chairs & Chairmats | J41: Global High-Back Leather Tilter, Burgundy | K41: Lodz | L41: Monday | M41: =VLOOKUP(L41,$U$2:$V$8,2,0) -> 1 | N41: -2426.55 | O41: 49 | P41: 5718.85 | Q41: 55713 | R41: =ISNUMBER(MATCH(Q41,'Returned order'!A:A,0)) -> FALSE | S41: 42037
A42: 25786 | B42: High | C42: 0.09 | D42: 122.99 | E42: 70 | F42: Annette Boone | G42: Corporate | H42: Furniture | I42: Chairs & Chairmats | J42: Global High-Back Leather Tilter, Burgundy | K42: Lodz | L42: Monday | M42: =VLOOKUP(L42,$U$2:$V$8,2,0) -> 1 | N42: -2426.55 | O42: 12 | P42: 1400.53 | Q42: 87947 | R42: =ISNUMBER(MATCH(Q42,'Returned order'!A:A,0)) -> FALSE | S42: 42037
A43: 18281 | B43: High | C43: 0.04 | D43: 296.18 | E43: 83 | F43: Edgar Stone | G43: Corporate | H43: Furniture | I43: Tables | J43: Hon 94000 Series Round Tables | K43: Lodz | L43: Sunday | M43: =VLOOKUP(L43,$U$2:$V$8,2,0) -> 7 | N43: -715.77821 | O43: 6 | P43: 1821.89 | Q43: 87365 | R43: =ISNUMBER(MATCH(Q43,'Returned order'!A:A,0)) -> FALSE | S43: 42078
A44: 23639 | B44: Not Specified | C44: 0 | D44: 8.09 | E44: 84 | F44: Helen Stein | G44: Consumer | H44: Furniture | I44: Office Furnishings | J44: 6" Cubicle Wall Clock, Black | K44: Lodz | L44: Monday | M44: =VLOOKUP(L44,$U$2:$V$8,2,0) -> 1 | N44: -144.56 | O44: 11 | P44: 90.98 | Q44: 87364 | R44: =ISNUMBER(MATCH(Q44,'Returned order'!A:A,0)) -> FALSE | S44: 42037
A45: 23880 | B45: High | C45: 0.08 | D45: 896.99 | E45: 84 | F45: Helen Stein | G45: Corporate | H45: Office Supplies | I45: Binders and Binder Accessories | J45: GBC DocuBind TL300 Electric Binding System | K45: Lodz | L45: Monday | M45: =VLOOKUP(L45,$U$2:$V$8,2,0) -> 1 | N45: 7402.32 | O45: 13 | P45: 10728 | Q45: 87366 | R45: =ISNUMBER(MATCH(Q45,'Returned order'!A:A,0)) -> FALSE | S45: 42093
A46: 24663 | B46: Low | C46: 0.05 | D46: 161.55 | E46: 87 | F46: Norman Shields | G46: Corporate | H46: Office Supplies | I46: Storage & Organization | J46: Fellowes Super Stor/Drawer® Files | K46: Warsaw | L46: Wednesday | M46: =VLOOKUP(L46,$U$2:$V$8,2,0) -> 3 | N46: 1892.424 | O46: 19 | P46: 3127.69 | Q46: 90596 | R46: =ISNUMBER(MATCH(Q46,'Returned order'!A:A,0)) -> FALSE | S46: 42158
...

Sheet Returned order
A1: Order ID | B1: Status
A2: 65 | B2: Returned
A3: 612 | B3: Returned
A4: 614 | B4: Returned
A5: 678 | B5: Returned
A6: 710 | B6: Returned
A7: 740 | B7: Returned
A8: 775 | B8: Returned
A9: 833 | B9: Returned
A10: 902 | B10: Returned
A11: 3300 | B11: Returned
A12: 3456 | B12: Returned
A13: 3525 | B13: Returned
... A1635: 182906 | B1635: Returned

Sheet Pivot Tables
B2: COUNTUNIQUE of Order ID | C2: Weekday helper | D2: Order Weekday
C3: 1 | D3: 1.00 Total | E3: 2 | F3: 2.00 Total | G3: 3 | H3: 3.00 Total | I3: 4 | J3: 4.00 Total | K3: 5 | L3: 5.00 Total | M3: 6 | N3: 6.00 Total | O3: 7 | P3: 7.00 Total
B4: City | C4: Monday | E4: Tuesday | G4: Wednesday | I4: Thursday | K4: Friday | M4: Saturday | O4: Sunday
B5: Krakow | C5: 53 | D5: 53 | E5: 48 | F5: 48 | G5: 57 | H5: 57 | I5: 65 | J5: 65 | K5: 65 | L5: 65 | M5: 58 | N5: 58 | O5: 54 | P5: 54 | AG5: Order returned | AH5: COUNTUNIQUE of Order ID | AI5: COUNTUNIQUE of Order ID | AO5: X | AP5: Y | AQ5: Color | AR5: Value
B6: Lodz | C6: 58 | D6: 58 | E6: 45 | F6: 45 | G6: 47 | H6: 47 | I6: 39 | J6: 39 | K6: 39 | L6: 39 | M6: 56 | N6: 56 | O6: 39 | P6: 39 | AD6: =AA6 -> Paper | AE6: =AB6 -> 284 | AG6: FALSE | AH6: 1354 | AI6: 0.99194139 | AN6: =AK6 -> Krakow | AO6: 2.5 | AP6: 1.5 | AQ6: 1 | AR6: =AL6 -> 77365.473
B7: Warsaw | C7: 43 | D7: 43 | E7: 38 | F7: 38 | G7: 56 | H7: 56 | I7: 57 | J7: 57 | K7: 44 | L7: 44 | M7: 60 | N7: 60 | O7: 38 | P7: 38 | AD7: =AA7 -> Binders and Binder Accessories | AE7: =AB7 -> 200 | AG7: TRUE | AH7: 11 | AI7: 0.0080586081 | AN7: =AK7 -> Lodz | AO7: 1.5 | AP7: 4.8 | AQ7: 2 | AR7: =AL7 -> 85291.403
B8: Wroclaw | C8: 44 | D8: 44 | E8: 44 | F8: 44 | G8: 40 | H8: 40 | I8: 62 | J8: 62 | K8: 46 | L8: 46 | M8: 50 | N8: 50 | O8: 40 | P8: 40 | AD8: =AA8 -> Telephones and Communication | AE8: =AB8 -> 194 | AG8: Grand Total | AH8: 1365 | AI8: 1 | AN8: =AK8 -> Warsaw | AO8: 3 | AP8: 5.8 | AQ8: 3 | AR8: =AL8 -> 75844.79
AD9: =AA9 -> Office Furnishings | AE9: =AB9 -> 185 | AN9: =AK9 -> Wroclaw | AO9: -1.5 | AP9: 3 | AQ9: 4 | AR9: =AL9 -> -14424.054
AD10: =AA10 -> Computer Peripherals | AE10: =AB10 -> 174 | AO10: 10 | AP10: 10
AO11: -5
BB30: =SUM(AU:AU) -> 1924337.9

Sheet Detail1-Lodz-1.00-Monday
A1: Unit Price | B1: Customer ID | C1: Customer Name | D1: Customer Segment | E1: Product Category | F1: Product Sub-Category | G1: Product Name | H1: City | I1: Order Weekday | J1: Weekday helper | K1: Profit | L1: Quantity ordered new | M1: Sales | N1: Order ID | O1: Order returned | P1: Order Date
A2: 3.8 | B2: 56 | C2: Randall Montgomery | D2: Consumer | E2: Office Supplies | F2: Binders and Binder Accessories | G2: Durable Pressboard Binders | H2: Lodz | I2: Monday | J2: 1 | K2: 19.6282 | L2: 20 | M2: 73.55 | N2: 88075 | O2: FALSE | P2: 42114
A3: 1.76 | B3: 56 | C3: Randall Montgomery | D3: Consumer | E3: Office Supplies | F3: Pens & Art Supplies | G3: Newell 310 | H3: Lodz | I3: Monday | J3: 1 | K3: -1.6524 | L3: 17 | M3: 29.57 | N3: 88075 | O3: FALSE | P3: 42114
A4: 122.99 | B4: 68 | C4: Scott Bunn | D4: Corporate | E4: Furniture | F4: Chairs & Chairmats | G4: Global High-Back Leather Tilter, Burgundy | H4: Lodz | I4: Monday | J4: 1 | K4: -2426.55 | L4: 49 | M4: 5718.85 | N4: 55713 | O4: FALSE | P4: 42037
A5: 122.99 | B5: 70 | C5: Annette Boone | D5: Corporate | E5: Furniture | F5: Chairs & Chairmats | G5: Global High-Back Leather Tilter, Burgundy | H5: Lodz | I5: Monday | J5: 1 | K5: -2426.55 | L5: 12 | M5: 1400.53 | N5: 87947 | O5: FALSE | P5: 42037
A6: 8.09 | B6: 84 | C6: Helen Stein | D6: Consumer | E6: Furniture | F6: Office Furnishings | G6: 6" Cubicle Wall Clock, Black | H6: Lodz | I6: Monday | J6: 1 | K6: -144.56 | L6: 11 | M6: 90.98 | N6: 87364 | O6: FALSE | P6: 42037
A7: 896.99 | B7: 84 | C7: Helen Stein | D7: Corporate | E7: Office Supplies | F7: Binders and Binder Accessories | G7: GBC DocuBind TL300 Electric Binding System | H7: Lodz | I7: Monday | J7: 1 | K7: 7402.32 | L7: 13 | M7: 10728 | N7: 87366 | O7: FALSE | P7: 42093
A8: 19.98 | B8: 101 | C8: Claudia Boyle | D8: Consumer | E8: Technology | F8: Computer Peripherals | G8: Belkin 105-Key Black Keyboard | H8: Lodz | I8: Monday | J8: 1 | K8: -16.2 | L8: 16 | M8: 303.59 | N8: 88205 | O8: FALSE | P8: 42177
A9: 300.98 | B9: 102 | C9: Caroline Johnston | D9: Consumer | E9: Furniture | F9: Bookcases | G9: Atlantic Metals Mobile 5-Shelf Bookcases, Custom Colors | H9: Lodz | I9: Monday | J9: 1 | K9: 2023.75 | L9: 31 | M9: 9459.94 | N9: 42599 | O9: FALSE | P9: 42100
A10: 19.98 | B10: 102 | C10: Caroline Johnston | D10: Consumer | E10: Technology | F10: Computer Peripherals | G10: Belkin 105-Key Black Keyboard | H10: Lodz | I10: Monday | J10: 1 | K10: -20.25 | L10: 65 | M10: 1233.32 | N10: 3397 | O10: FALSE | P10: 42177
A11: 2.88 | B11: 102 | C11: Caroline Johnston | D11: Consumer | E11: Office Supplies | F11: Binders and Binder Accessories | G11: Avery Durable Binders | H11: Lodz | I11: Monday | J11: 1 | K11: -3.381 | L11: 17 | M11: 47.31 | N11: 3397 | O11: FALSE | P11: 42177
A12: 300.98 | B12: 107 | C12: Lois Hamilton | D12: Consumer | E12: Furniture | F12: Bookcases | G12: Atlantic Metals Mobile 5-Shelf Bookcases, Custom Colors | H12: Lodz | I12: Monday | J12: 1 | K12: 1684.4763 | L12: 8 | M12: 2441.27 | N12: 88204 | O12: FALSE | P12: 42100
A13: 2.88 | B13: 109 | C13: Tom McFarland | D13: Consumer | E13: Office Supplies | F13: Binders and Binder Accessories | G13: Avery Durable Binders | H13: Lodz | I13: Monday | J13: 1 | K13: -2.7048 | L13: 4 | M13: 11.13 | N13: 88205 | O13: FALSE | P13: 42177
... A85: 3.57 | B85: 3374 | C85: Jamie Ward | D85: Home Office | E85: Office Supplies | F85: Pens & Art Supplies | G85: Barrel Sharpener | H85: Lodz | I85: Monday | J85: 1 | K85: -56.888 | L85: 9 | M85: 31.45 | N85: 87474 | O85: FALSE | P85: 42184

Sheet Dashboard
F9: =AE19 -> Monday | G9: =AF19 | H9: =AH19 | I9: =AJ19 | J9: =AL19 | K9: =AN19 | L9: =AP19
E10: =AD20 -> Krakow | F10: =AE20 -> 53 | G10: =AF20 -> 53 | H10: =AH20 -> 48 | I10: =AJ20 -> 57 | J10: =AK20 -> 65 | K10: =AN20 -> 65 | L10: =AP20 -> 58
E11: =AD21 -> Lodz | F11: =AE21 -> 58 | G11: 45 | H11: 47 | I11: 39 | J11: 39 | K11: 56 | L11: 39
E12: =AD22 -> Warsaw | F12: =AE22 -> 43 | G12: 38 | H12: 56 | I12: 57 | J12: 44 | K12: 60 | L12: 38
E13: =AD23 -> Wroclaw | F13: =AE23 -> 44 | G13: 44 | H13: 40 | I13: 62 | J13: 46 | K13: 50 | L13: 40
AD17: COUNTUNIQUE of Order ID | AE17: Weekday helper | AF17: Order Weekday
Z18: =SUM(BW:BW) -> 224077.61 | AE18: 1 | AF18: 1.00 Total | AG18: 2 | AH18: 2.00 Total | AI18: 3 | AJ18: 3.00 Total | AK18: 4 | AL18: 4.00 Total | AM18: 5 | AN18: 5.00 Total | AO18: 6 | AP18: 6.00 Total | AQ18: 7 | AR18: 7.00 Total
AD19: City | AE19: Monday | AG19: Tuesday | AI19: Wednesday | AK19: Thursday | AM19: Friday | AO19: Saturday | AQ19: Sunday
AD20: Krakow | AE20: 53 | AF20: 53 | AG20: 48 | AH20: 48 | AI20: 57 | AJ20: 57 | AK20: 65 | AL20: 65 | AM20: 65 | AN20: 65 | AO20: 58 | AP20: 58 | AQ20: 54 | AR20: 54 | BH20: Order returned | BI20: COUNTUNIQUE of Order ID | BJ20: COUNTUNIQUE of Order ID | BP20: X | BQ20: Y | BR20: Color | BS20: Value
AD21: Lodz | AE21: 58 | AF21: 58 | AG21: 45 | AH21: 45 | AI21: 47 | AJ21: 47 | AK21: 39 | AL21: 39 | AM21: 39 | AN21: 39 | AO21: 56 | AP21: 56 | AQ21: 39 | AR21: 39 | BE21: =BB21 -> Paper | BF21: =BC21 -> 284 | BH21: FALSE | BI21: 1354 | BJ21: 0.99194139 | BO21: =BL21 -> Krakow | BP21: 2.5 | BQ21: 1.5 | BR21: 1 | BS21: =BM21 -> 77365.473
AD22: Warsaw | AE22: 43 | AF22: 43 | AG22: 38 | AH22: 38 | AI22: 56 | AJ22: 56 | AK22: 57 | AL22: 57 | AM22: 44 | AN22: 44 | AO22: 60 | AP22: 60 | AQ22: 38 | AR22: 38 | BE22: =BB22 -> Binders and Binder Accessories | BF22: =BC22 -> 200 | BH22: TRUE | BI22: 11 | BJ22: 0.0080586081 | BO22: =BL22 -> Lodz | BP22: 1.5 | BQ22: 4.8 | BR22: 2 | BS22: =BM22 -> 85291.403
AD23: Wroclaw | AE23: 44 | AF23: 44 | AG23: 44 | AH23: 44 | AI23: 40 | AJ23: 40 | AK23: 62 | AL23: 62 | AM23: 46 | AN23: 46 | AO23: 50 | AP23: 50 | AQ23: 40 | AR23: 40 | BE23: =BB23 -> Telephones and Communication | BF23: =BC23 -> 194 | BH23: Grand Total | BI23: 1365 | BJ23: 1 | BO23: =BL23 -> Warsaw | BP23: 3 | BQ23: 5.8 | BR23: 3 | BS23: =BM23 -> 75844.79
BE24: =BB24 -> Office Furnishings | BF24: =BC24 -> 185 | BO24: =BL24 -> Wroclaw | BP24: -1.5 | BQ24: 3 | BR24: 4 | BS24: =BM24 -> -14424.054
BE25: =BB25 -> Computer Peripherals | BF25: =BC25 -> 174 | BP25: 10 | BQ25: 10
Z26: =SUM(BV:BV) -> 1924337.9 | BP26: -5
O36: =BO21 -> Krakow | P36: =BS21 -> 77365.473
O37: =BO22 -> Lodz | P37: =BS22 -> 85291.403
O38: =BO23 -> Warsaw | P38: =BS23 -> 75844.79
O39: =BO24 -> Wroclaw | P39: =BS24 -> -14424.054
E50: =BI23 -> 1365 | H50: =BI22 -> 11 | K50: =BJ22 -> 0.0080586081
